<sdf version='1.7'>
  <world name='default'>
    <plugin name='gazebo_ros_state' filename='libgazebo_ros_state.so'>
      <ros>
        <namespace>/gazebo</namespace>
      </ros>
      <update_rate>1.0</update_rate>
    </plugin>
    <light name='sun' type='directional'>
      <cast_shadows>1</cast_shadows>
      <pose>0 0 10 0 -0 0</pose>
      <diffuse>0.8 0.8 0.8 1</diffuse>
      <specular>0.2 0.2 0.2 1</specular>
      <attenuation>
        <range>1000</range>
        <constant>0.9</constant>
        <linear>0.01</linear>
        <quadratic>0.001</quadratic>
      </attenuation>
      <direction>-0.5 0.1 -0.9</direction>
      <spot>
        <inner_angle>0</inner_angle>
        <outer_angle>0</outer_angle>
        <falloff>0</falloff>
      </spot>
    </light>
    <model name='ground_plane'>
      <static>1</static>
      <link name='link'>
        <collision name='collision'>
          <geometry>
            <plane>
              <normal>0 0 1</normal>
              <size>100 100</size>
            </plane>
          </geometry>
          <surface>
            <contact>
              <collide_bitmask>65535</collide_bitmask>
              <ode/>
            </contact>
            <friction>
              <ode>
                <mu>100</mu>
                <mu2>50</mu2>
              </ode>
              <torsional>
                <ode/>
              </torsional>
            </friction>
            <bounce/>
          </surface>
          <max_contacts>10</max_contacts>
        </collision>
        <visual name='visual'>
          <cast_shadows>0</cast_shadows>
          <geometry>
            <plane>
              <normal>0 0 1</normal>
              <size>100 100</size>
            </plane>
          </geometry>
          <material>
            <script>
              <uri>file://media/materials/scripts/gazebo.material</uri>
              <name>Gazebo/Grey</name>
            </script>
          </material>
        </visual>
        <self_collide>0</self_collide>
        <enable_wind>0</enable_wind>
        <kinematic>0</kinematic>
      </link>
    </model>
    <gravity>0 0 -9.8</gravity>
    <magnetic_field>6e-06 2.3e-05 -4.2e-05</magnetic_field>
    <atmosphere type='adiabatic'/>
    <physics type='ode'>
      <max_step_size>0.001</max_step_size>
      <real_time_factor>1</real_time_factor>
      <real_time_update_rate>1000</real_time_update_rate>
    </physics>
    <scene>
      <ambient>0.4 0.4 0.4 1</ambient>
      <background>0.7 0.7 0.7 1</background>
      <shadows>1</shadows>
    </scene>
    <wind/>
    <spherical_coordinates>
      <surface_model>EARTH_WGS84</surface_model>
      <latitude_deg>0</latitude_deg>
      <longitude_deg>0</longitude_deg>
      <elevation>0</elevation>
      <heading_deg>0</heading_deg>
    </spherical_coordinates>
    <state world_name='default'>
      <sim_time>94 392000000</sim_time>
      <real_time>71 364225834</real_time>
      <wall_time>1657797711 114255026</wall_time>
      <iterations>68623</iterations>
      <model name='ai_path_planner'>
        <pose>0 0 0 7e-06 -1e-06 -2e-06</pose>
        <scale>1 1 1</scale>
        <link name='base_0'>
          <pose>0 0 0 7e-06 -1e-06 -2e-06</pose>
          <velocity>1e-06 1e-06 -0 7e-06 -6e-06 -1e-05</velocity>
          <acceleration>1e-06 -1e-06 -0 -2.5e-05 4.2e-05 3.4e-05</acceleration>
          <wrench>3e-06 -2e-06 -1e-06 0 -0 0</wrench>
        </link>
        <link name='link1'>
          <pose>-0 -1e-06 0.194999 -2.3e-05 -1e-06 1.5e-05</pose>
          <velocity>0 0 -0 4e-06 -4e-06 6.9e-05</velocity>
          <acceleration>-5e-06 -1e-06 -0 -1.6e-05 -0.000107 9.8e-05</acceleration>
          <wrench>-3.7e-05 -7e-06 -1e-06 0 -0 0</wrench>
        </link>
        <link name='link2'>
          <pose>-1e-06 0.039 0.194998 -3.11138 -1.57055 1.54039</pose>
          <velocity>-2e-06 0 0 0 7.3e-05 8.5e-05</velocity>
          <acceleration>-2.3e-05 -1e-06 -0 0.000117 0.000459 0.026397</acceleration>
          <wrench>-0.000255 -9e-06 -5e-06 0 -0 0</wrench>
        </link>
        <link name='link3'>
          <pose>4e-06 0.039136 0.754998 -1.57104 0.000212 -0.000194</pose>
          <velocity>4e-05 0 0 0 5.5e-05 8.4e-05</velocity>
          <acceleration>-3.1e-05 1e-06 -0 0.000177 -0.036548 0.006103</acceleration>
          <wrench>-9e-05 2e-06 -1e-06 0 -0 0</wrench>
        </link>
        <link name='link4'>
          <pose>0.000113 0.039268 1.271 -4.9e-05 0.000213 -0.000187</pose>
          <velocity>6.7e-05 -0 0 0 5.6e-05 9e-05</velocity>
          <acceleration>2.4e-05 1e-06 -1e-06 1.2e-05 0.000482 0.000103</acceleration>
          <wrench>7.7e-05 5e-06 -2e-06 0 -0 0</wrench>
        </link>
        <link name='link5'>
          <pose>0.000113 0.039268 1.271 -1.57105 0.000212 -0.000187</pose>
          <velocity>6.7e-05 -0 0 0 5.7e-05 9e-05</velocity>
          <acceleration>0.000106 1e-06 -2e-06 9e-06 0.000251 0.000475</acceleration>
          <wrench>0.000227 1e-06 -4e-06 0 -0 0</wrench>
        </link>
        <link name='link6'>
          <pose>0.00014 0.039299 1.395 -4.9e-05 0.000212 -0.000187</pose>
          <velocity>7.4e-05 -0 0 0 5.7e-05 8.9e-05</velocity>
          <acceleration>0.000146 -0 -2e-06 1e-05 0.000517 0.000157</acceleration>
          <wrench>0.000114 -0 -2e-06 0 -0 0</wrench>
        </link>
      </model>
      <model name='ground_plane'>
        <pose>0 0 0 0 -0 0</pose>
        <scale>1 1 1</scale>
        <link name='link'>
          <pose>0 0 0 0 -0 0</pose>
          <velocity>0 0 0 0 -0 0</velocity>
          <acceleration>0 0 0 0 -0 0</acceleration>
          <wrench>0 0 0 0 -0 0</wrench>
        </link>
      </model>
      <model name='unit_box'>
        <pose>1.05657 0.029117 0.499999 -1e-06 3e-06 -2e-06</pose>
        <scale>1 0.12424 1</scale>
        <link name='link'>
          <pose>1.05657 0.029117 0.499999 -1e-06 3e-06 -2e-06</pose>
          <velocity>0 0 0 0 -0 0</velocity>
          <acceleration>3.71934 -0.462231 -3.60107 0.923803 1.15555 0.000399</acceleration>
          <wrench>3.71934 -0.462231 -3.60107 0 -0 0</wrench>
        </link>
      </model>
      <light name='sun'>
        <pose>0 0 10 0 -0 0</pose>
      </light>
    </state>
    <gui fullscreen='0'>
      <camera name='user_camera'>
        <pose>5.44722 -0.116673 7.68196 0 1.0938 3.0082</pose>
        <view_controller>orbit</view_controller>
        <projection_type>perspective</projection_type>
      </camera>
    </gui>
    <model name='ai_path_planner'>
      <joint name='world_fixed' type='fixed'>
        <pose relative_to='__model__'>0 0 0 0 -0 0</pose>
        <parent>world</parent>
        <child>base_0</child>
      </joint>
      <link name='base_0'>
        <pose relative_to='world_fixed'>0 0 0 0 -0 0</pose>
        <inertial>
          <pose>4e-06 -0.001016 0.08181 0 -0 0</pose>
          <mass>3.635</mass>
          <inertia>
            <ixx>0.02216</ixx>
            <ixy>5.8001e-06</ixy>
            <ixz>6.1941e-06</ixz>
            <iyy>0.024835</iyy>
            <iyz>-5.3034e-05</iyz>
            <izz>0.021063</izz>
          </inertia>
        </inertial>
        <collision name='base_0_collision'>
          <pose>0 0 0 0 -0 0</pose>
          <geometry>
            <mesh>
              <scale>0.001 0.001 0.001</scale>
              <uri>file:////home/markus/robotPP_ws/install/ai_path_planner_pkg/share/ai_path_planner_pkg/description/meshes/a0912_blue/A0912_0_0.dae</uri>
            </mesh>
          </geometry>
          <surface>
            <contact>
              <ode>
                <kp>1e+06</kp>
                <kd>100</kd>
                <max_vel>1</max_vel>
                <min_depth>0.001</min_depth>
              </ode>
            </contact>
            <friction>
              <ode>
                <mu>30</mu>
                <mu2>30</mu2>
              </ode>
              <torsional>
                <ode/>
              </torsional>
            </friction>
            <bounce/>
          </surface>
          <max_contacts>10</max_contacts>
        </collision>
        <visual name='base_0_visual'>
          <pose>0 0 0 0 -0 0</pose>
          <geometry>
            <mesh>
              <scale>0.001 0.001 0.001</scale>
              <uri>file:////home/markus/robotPP_ws/install/ai_path_planner_pkg/share/ai_path_planner_pkg/description/meshes/a0912_blue/A0912_0_0.dae</uri>
            </mesh>
          </geometry>
        </visual>
        <self_collide>0</self_collide>
        <enable_wind>0</enable_wind>
        <kinematic>0</kinematic>
      </link>
      <joint name='joint1' type='revolute'>
        <pose relative_to='base_0'>0 0 0.195 0 -0 0</pose>
        <parent>base_0</parent>
        <child>link1</child>
        <axis>
          <xyz>0 0 1</xyz>
          <limit>
            <lower>-6.2832</lower>
            <upper>6.2832</upper>
            <effort>411</effort>
            <velocity>3.1416</velocity>
          </limit>
          <dynamics>
            <damping>60</damping>
            <friction>4</friction>
            <spring_reference>0</spring_reference>
            <spring_stiffness>0</spring_stiffness>
          </dynamics>
        </axis>
      </joint>
      <link name='link1'>
        <pose relative_to='joint1'>0 0 0 0 -0 0</pose>
        <inertial>
          <pose>4.4e-05 0.029982 -0.01112 0 -0 0</pose>
          <mass>7.863</mass>
          <inertia>
            <ixx>0.045839</ixx>
            <ixy>1.2759e-05</ixy>
            <ixz>-3.6168e-05</ixz>
            <iyy>0.032913</iyy>
            <iyz>-0.0029965</iyz>
            <izz>0.044399</izz>
          </inertia>
        </inertial>
        <collision name='link1_collision'>
          <pose>0 0 0 0 -0 0</pose>
          <geometry>
            <cylinder>
              <length>0.2</length>
              <radius>0.08</radius>
            </cylinder>
          </geometry>
          <surface>
            <contact>
              <ode>
                <kp>1e+06</kp>
                <kd>100</kd>
                <max_vel>1</max_vel>
                <min_depth>0.001</min_depth>
              </ode>
            </contact>
            <friction>
              <ode>
                <mu>30</mu>
                <mu2>30</mu2>
              </ode>
              <torsional>
                <ode/>
              </torsional>
            </friction>
            <bounce/>
          </surface>
          <max_contacts>10</max_contacts>
        </collision>
        <visual name='link1_visual'>
          <pose>0 0 0 0 -0 0</pose>
          <geometry>
            <mesh>
              <scale>0.001 0.001 0.001</scale>
              <uri>file:////home/markus/robotPP_ws/install/ai_path_planner_pkg/share/ai_path_planner_pkg/description/meshes/a0912_blue/A0912_1_0.dae</uri>
            </mesh>
          </geometry>
        </visual>
        <visual name='link1_visual_1'>
          <pose>0 0 0 0 -0 0</pose>
          <geometry>
            <mesh>
              <scale>0.001 0.001 0.001</scale>
              <uri>file:////home/markus/robotPP_ws/install/ai_path_planner_pkg/share/ai_path_planner_pkg/description/meshes/a0912_blue/A0912_1_1.dae</uri>
            </mesh>
          </geometry>
        </visual>
        <visual name='link1_visual_2'>
          <pose>0 0 0 0 -0 0</pose>
          <geometry>
            <mesh>
              <scale>0.001 0.001 0.001</scale>
              <uri>file:////home/markus/robotPP_ws/install/ai_path_planner_pkg/share/ai_path_planner_pkg/description/meshes/a0912_blue/A0912_1_2.dae</uri>
            </mesh>
          </geometry>
        </visual>
        <self_collide>0</self_collide>
        <enable_wind>0</enable_wind>
        <kinematic>0</kinematic>
      </link>
      <joint name='joint2' type='revolute'>
        <pose relative_to='link1'>0 0.039 0 3.14159 -1.57059 1.57059</pose>
        <parent>link1</parent>
        <child>link2</child>
        <axis>
          <xyz>0 0 1</xyz>
          <limit>
            <lower>-6.2832</lower>
            <upper>6.2832</upper>
            <effort>411</effort>
            <velocity>3.1416</velocity>
          </limit>
          <dynamics>
            <damping>50</damping>
            <friction>3</friction>
            <spring_reference>0</spring_reference>
            <spring_stiffness>0</spring_stiffness>
          </dynamics>
        </axis>
      </joint>
      <link name='link2'>
        <pose relative_to='joint2'>0 0 0 0 -0 0</pose>
        <inertial>
          <pose>0.19748 0.001426 0.13191 0 -0 0</pose>
          <mass>10.985</mass>
          <inertia>
            <ixx>0.04446</ixx>
            <ixy>-0.0049948</ixy>
            <ixz>-0.010992</ixz>
            <iyy>0.67642</iyy>
            <iyz>-2.8483e-05</iyz>
            <izz>0.67428</izz>
          </inertia>
        </inertial>
        <collision name='link2_collision'>
          <pose>0.3 0 0.1525 3.14159 -1.57079 3.14159</pose>
          <geometry>
            <cylinder>
              <length>0.6</length>
              <radius>0.08</radius>
            </cylinder>
          </geometry>
          <surface>
            <contact>
              <ode>
                <kp>1e+06</kp>
                <kd>100</kd>
                <max_vel>1</max_vel>
                <min_depth>0.001</min_depth>
              </ode>
            </contact>
            <friction>
              <ode>
                <mu>30</mu>
                <mu2>30</mu2>
              </ode>
              <torsional>
                <ode/>
              </torsional>
            </friction>
            <bounce/>
          </surface>
          <max_contacts>10</max_contacts>
        </collision>
        <visual name='link2_visual'>
          <pose>0 0 0 0 -0 0</pose>
          <geometry>
            <mesh>
              <scale>0.001 0.001 0.001</scale>
              <uri>file:////home/markus/robotPP_ws/install/ai_path_planner_pkg/share/ai_path_planner_pkg/description/meshes/a0912_blue/A0912_2_0.dae</uri>
            </mesh>
          </geometry>
        </visual>
        <visual name='link2_visual_1'>
          <pose>0 0 0 0 -0 0</pose>
          <geometry>
            <mesh>
              <scale>0.001 0.001 0.001</scale>
              <uri>file:////home/markus/robotPP_ws/install/ai_path_planner_pkg/share/ai_path_planner_pkg/description/meshes/a0912_blue/A0912_2_1.dae</uri>
            </mesh>
          </geometry>
        </visual>
        <visual name='link2_visual_2'>
          <pose>0 0 0 0 -0 0</pose>
          <geometry>
            <mesh>
              <scale>0.001 0.001 0.001</scale>
              <uri>file:////home/markus/robotPP_ws/install/ai_path_planner_pkg/share/ai_path_planner_pkg/description/meshes/a0912_blue/A0912_2_2.dae</uri>
            </mesh>
          </geometry>
        </visual>
        <self_collide>0</self_collide>
        <enable_wind>0</enable_wind>
        <kinematic>0</kinematic>
      </link>
      <joint name='joint3' type='revolute'>
        <pose relative_to='link2'>0.56 0 0 0 -0 1.571</pose>
        <parent>link2</parent>
        <child>link3</child>
        <axis>
          <xyz>0 0 1</xyz>
          <limit>
            <lower>-2.7925</lower>
            <upper>2.7925</upper>
            <effort>194</effort>
            <velocity>3.1416</velocity>
          </limit>
          <dynamics>
            <damping>40</damping>
            <friction>2</friction>
            <spring_reference>0</spring_reference>
            <spring_stiffness>0</spring_stiffness>
          </dynamics>
        </axis>
      </joint>
      <link name='link3'>
        <pose relative_to='joint3'>0 0 0 0 -0 0</pose>
        <inertial>
          <pose>8.5e-05 -0.002513 0.032058 0 -0 0</pose>
          <mass>2.881</mass>
          <inertia>
            <ixx>0.012756</ixx>
            <ixy>-5.4257e-06</ixy>
            <ixz>1.6402e-05</ixz>
            <iyy>0.011416</iyy>
            <iyz>-0.0001989</iyz>
            <izz>0.0080652</izz>
          </inertia>
        </inertial>
        <visual name='link3_visual'>
          <pose>0 0 0 0 -0 0</pose>
          <geometry>
            <mesh>
              <scale>0.001 0.001 0.001</scale>
              <uri>file:////home/markus/robotPP_ws/install/ai_path_planner_pkg/share/ai_path_planner_pkg/description/meshes/a0912_blue/A0912_3_0.dae</uri>
            </mesh>
          </geometry>
        </visual>
        <visual name='link3_visual_1'>
          <pose>0 0 0 0 -0 0</pose>
          <geometry>
            <mesh>
              <scale>0.001 0.001 0.001</scale>
              <uri>file:////home/markus/robotPP_ws/install/ai_path_planner_pkg/share/ai_path_planner_pkg/description/meshes/a0912_blue/A0912_3_1.dae</uri>
            </mesh>
          </geometry>
        </visual>
        <self_collide>0</self_collide>
        <enable_wind>0</enable_wind>
        <kinematic>0</kinematic>
      </link>
      <joint name='joint4' type='revolute'>
        <pose relative_to='link3'>0 -0.516 0 1.571 -0 0</pose>
        <parent>link3</parent>
        <child>link4</child>
        <axis>
          <xyz>0 0 1</xyz>
          <limit>
            <lower>-6.2832</lower>
            <upper>6.2832</upper>
            <effort>50</effort>
            <velocity>6.2832</velocity>
          </limit>
          <dynamics>
            <damping>20</damping>
            <friction>1</friction>
            <spring_reference>0</spring_reference>
            <spring_stiffness>0</spring_stiffness>
          </dynamics>
        </axis>
      </joint>
      <link name='link4'>
        <pose relative_to='joint4'>0 0 0 0 -0 0</pose>
        <inertial>
          <pose>-9.6e-05 0.085314 -0.13975 0 -0 0</pose>
          <mass>3.273</mass>
          <inertia>
            <ixx>0.12246</ixx>
            <ixy>2.3905e-05</ixy>
            <ixz>2.5022e-05</ixz>
            <iyy>0.11307</iyy>
            <iyz>-0.027995</iyz>
            <izz>0.017186</izz>
          </inertia>
        </inertial>
        <collision name='link4_collision'>
          <pose>0 0.075 -0.2 -0.46 0 0</pose>
          <geometry>
            <cylinder>
              <length>0.4</length>
              <radius>0.05</radius>
            </cylinder>
          </geometry>
          <surface>
            <contact>
              <ode>
                <kp>1e+06</kp>
                <kd>100</kd>
                <max_vel>1</max_vel>
                <min_depth>0.001</min_depth>
              </ode>
            </contact>
            <friction>
              <ode>
                <mu>30</mu>
                <mu2>30</mu2>
              </ode>
              <torsional>
                <ode/>
              </torsional>
            </friction>
            <bounce/>
          </surface>
          <max_contacts>10</max_contacts>
        </collision>
        <visual name='link4_visual'>
          <pose>0 0 0 0 -0 0</pose>
          <geometry>
            <mesh>
              <scale>0.001 0.001 0.001</scale>
              <uri>file:////home/markus/robotPP_ws/install/ai_path_planner_pkg/share/ai_path_planner_pkg/description/meshes/a0912_blue/A0912_4_0.dae</uri>
            </mesh>
          </geometry>
        </visual>
        <visual name='link4_visual_1'>
          <pose>0 0 0 0 -0 0</pose>
          <geometry>
            <mesh>
              <scale>0.001 0.001 0.001</scale>
              <uri>file:////home/markus/robotPP_ws/install/ai_path_planner_pkg/share/ai_path_planner_pkg/description/meshes/a0912_blue/A0912_4_1.dae</uri>
            </mesh>
          </geometry>
        </visual>
        <self_collide>0</self_collide>
        <enable_wind>0</enable_wind>
        <kinematic>0</kinematic>
      </link>
      <joint name='joint5' type='revolute'>
        <pose relative_to='link4'>0 0 0 -1.571 0 0</pose>
        <parent>link4</parent>
        <child>link5</child>
        <axis>
          <xyz>0 0 1</xyz>
          <limit>
            <lower>-6.2832</lower>
            <upper>6.2832</upper>
            <effort>50</effort>
            <velocity>6.2832</velocity>
          </limit>
          <dynamics>
            <damping>10</damping>
            <friction>1</friction>
            <spring_reference>0</spring_reference>
            <spring_stiffness>0</spring_stiffness>
          </dynamics>
        </axis>
      </joint>
      <link name='link5'>
        <pose relative_to='joint5'>0 0 0 0 -0 0</pose>
        <inertial>
          <pose>0.000109 -0.003286 0.01477 0 -0 0</pose>
          <mass>2.141</mass>
          <inertia>
            <ixx>0.013145</ixx>
            <ixy>-4.7132e-06</ixy>
            <ixz>8.5804e-06</ixz>
            <iyy>0.0073072</iyy>
            <iyz>-5.999e-05</iyz>
            <izz>0.0090476</izz>
          </inertia>
        </inertial>
        <collision name='link5_collision'>
          <pose>0 0 0 1.571 -0 0</pose>
          <geometry>
            <cylinder>
              <length>0.15</length>
              <radius>0.06</radius>
            </cylinder>
          </geometry>
          <surface>
            <contact>
              <ode>
                <kp>1e+06</kp>
                <kd>100</kd>
                <max_vel>1</max_vel>
                <min_depth>0.001</min_depth>
              </ode>
            </contact>
            <friction>
              <ode>
                <mu>30</mu>
                <mu2>30</mu2>
              </ode>
              <torsional>
                <ode/>
              </torsional>
            </friction>
            <bounce/>
          </surface>
          <max_contacts>10</max_contacts>
        </collision>
        <visual name='link5_visual'>
          <pose>0 0 0 0 -0 0</pose>
          <geometry>
            <mesh>
              <scale>0.001 0.001 0.001</scale>
              <uri>file:////home/markus/robotPP_ws/install/ai_path_planner_pkg/share/ai_path_planner_pkg/description/meshes/a0912_blue/A0912_5_0.dae</uri>
            </mesh>
          </geometry>
        </visual>
        <visual name='link5_visual_1'>
          <pose>0 0 0 0 -0 0</pose>
          <geometry>
            <mesh>
              <scale>0.001 0.001 0.001</scale>
              <uri>file:////home/markus/robotPP_ws/install/ai_path_planner_pkg/share/ai_path_planner_pkg/description/meshes/a0912_blue/A0912_5_1.dae</uri>
            </mesh>
          </geometry>
        </visual>
        <self_collide>0</self_collide>
        <enable_wind>0</enable_wind>
        <kinematic>0</kinematic>
      </link>
      <joint name='joint6' type='revolute'>
        <pose relative_to='link5'>0 -0.124 0 1.571 -0 0</pose>
        <parent>link5</parent>
        <child>link6</child>
        <axis>
          <xyz>0 0 1</xyz>
          <limit>
            <lower>-6.2832</lower>
            <upper>6.2832</upper>
            <effort>50</effort>
            <velocity>6.2832</velocity>
          </limit>
          <dynamics>
            <damping>10</damping>
            <friction>1</friction>
            <spring_reference>0</spring_reference>
            <spring_stiffness>0</spring_stiffness>
          </dynamics>
        </axis>
      </joint>
      <link name='link6'>
        <pose relative_to='joint6'>0 0 0 0 -0 0</pose>
        <inertial>
          <pose>-1.9e-05 -6e-06 -0.05227 0 -0 0</pose>
          <mass>0.784</mass>
          <inertia>
            <ixx>0.0067403</ixx>
            <ixy>5.2373e-06</ixy>
            <ixz>2.4957e-06</ixz>
            <iyy>0.0048015</iyy>
            <iyz>8.3671e-06</iyz>
            <izz>0.0059696</izz>
          </inertia>
        </inertial>
        <collision name='link6_collision'>
          <pose>0 0 0 0 -0 0</pose>
          <geometry>
            <mesh>
              <scale>0.001 0.001 0.001</scale>
              <uri>file:////home/markus/robotPP_ws/install/ai_path_planner_pkg/share/ai_path_planner_pkg/description/meshes/a0912_blue/A0912_6_0.dae</uri>
            </mesh>
          </geometry>
          <surface>
            <contact>
              <ode>
                <kp>1e+06</kp>
                <kd>100</kd>
                <max_vel>1</max_vel>
                <min_depth>0.001</min_depth>
              </ode>
            </contact>
            <friction>
              <ode>
                <mu>30</mu>
                <mu2>30</mu2>
              </ode>
              <torsional>
                <ode/>
              </torsional>
            </friction>
            <bounce/>
          </surface>
          <max_contacts>10</max_contacts>
        </collision>
        <visual name='link6_visual'>
          <pose>0 0 0 0 -0 0</pose>
          <geometry>
            <mesh>
              <scale>0.001 0.001 0.001</scale>
              <uri>file:////home/markus/robotPP_ws/install/ai_path_planner_pkg/share/ai_path_planner_pkg/description/meshes/a0912_blue/A0912_6_0.dae</uri>
            </mesh>
          </geometry>
        </visual>
        <sensor name='end_effector_sensor' type='contact'>
          <update_rate>50</update_rate>
          <contact>
            <collision>link6_collision</collision>
            <topic>__default_topic__</topic>
          </contact>
          <plugin name='gazebo_ros_bumper_sensor' filename='libgazebo_ros_bumper.so'>
            <ros>
              <namespace>contact_sensor</namespace>
              <remapping>bumper_states:=bumper_link6</remapping>
            </ros>
            <frame_name>link6</frame_name>
          </plugin>
          <selfCollide>1</selfCollide>
          <alwaysOn>1</alwaysOn>
        </sensor>
        <self_collide>0</self_collide>
        <enable_wind>0</enable_wind>
        <kinematic>0</kinematic>
      </link>
      <static>0</static>
      <plugin name='gazebo_ros2_control' filename='libgazebo_ros2_control.so'>
        <robot_sim_type>gazebo_ros2_control/GazeboSystem</robot_sim_type>
        <parameters>/home/markus/robotPP_ws/install/ai_path_planner_pkg/share/ai_path_planner_pkg/config/simple_controller.yaml</parameters>
      </plugin>
      <pose>0 0 0 0 -0 0</pose>
    </model>
    <model name='unit_box'>
      <pose>1.05657 0.029117 0.5 0 -0 0</pose>
      <link name='link'>
        <inertial>
          <mass>1</mass>
          <inertia>
            <ixx>0.166667</ixx>
            <ixy>0</ixy>
            <ixz>0</ixz>
            <iyy>0.166667</iyy>
            <iyz>0</iyz>
            <izz>0.166667</izz>
          </inertia>
          <pose>0 0 0 0 -0 0</pose>
        </inertial>
        <collision name='collision'>
          <geometry>
            <box>
              <size>1 0.999997 1</size>
            </box>
          </geometry>
          <max_contacts>10</max_contacts>
          <surface>
            <contact>
              <ode/>
            </contact>
            <bounce/>
            <friction>
              <torsional>
                <ode/>
              </torsional>
              <ode/>
            </friction>
          </surface>
        </collision>
        <visual name='visual'>
          <geometry>
            <box>
              <size>1 0.999997 1</size>
            </box>
          </geometry>
          <material>
            <script>
              <name>Gazebo/Blue</name>
              <uri>file://media/materials/scripts/gazebo.material</uri>
            </script>
          </material>
        </visual>
        <self_collide>0</self_collide>
        <enable_wind>0</enable_wind>
        <kinematic>0</kinematic>
      </link>
    </model>
  </world>
</sdf>
